
  0%|                                                                                                                   | 0/771 [00:00<?, ?it/s]Exception ignored in: <function _MultiProcessingDataLoaderIter.__del__ at 0x7f9d57379c60>
Traceback (most recent call last):
  File "/home/user/anaconda3/envs/llava/lib/python3.10/site-packages/torch/utils/data/dataloader.py", line 1478, in __del__
    self._shutdown_workers()
  File "/home/user/anaconda3/envs/llava/lib/python3.10/site-packages/torch/utils/data/dataloader.py", line 1442, in _shutdown_workers
    w.join(timeout=_utils.MP_STATUS_CHECK_INTERVAL)
  File "/home/user/anaconda3/envs/llava/lib/python3.10/multiprocessing/process.py", line 149, in join
    res = self._popen.wait(timeout)
  File "/home/user/anaconda3/envs/llava/lib/python3.10/multiprocessing/popen_fork.py", line 40, in wait
    if not wait([self.sentinel], timeout):
  File "/home/user/anaconda3/envs/llava/lib/python3.10/multiprocessing/connection.py", line 931, in wait
    ready = selector.select(timeout)
  File "/home/user/anaconda3/envs/llava/lib/python3.10/selectors.py", line 416, in select
    fd_event_list = self._selector.poll(timeout)
KeyboardInterrupt:
Traceback (most recent call last):
  File "/home/user/anaconda3/envs/llava/lib/python3.10/runpy.py", line 196, in _run_module_as_main
    return _run_code(code, main_globals, None,
  File "/home/user/anaconda3/envs/llava/lib/python3.10/runpy.py", line 86, in _run_code
    exec(code, run_globals)
  File "/home/user/.vscode-server/extensions/ms-python.debugpy-2024.10.0-linux-x64/bundled/libs/debugpy/adapter/../../debugpy/launcher/../../debugpy/__main__.py", line 39, in <module>
    cli.main()
  File "/home/user/.vscode-server/extensions/ms-python.debugpy-2024.10.0-linux-x64/bundled/libs/debugpy/adapter/../../debugpy/launcher/../../debugpy/../debugpy/server/cli.py", line 430, in main
    run()
  File "/home/user/.vscode-server/extensions/ms-python.debugpy-2024.10.0-linux-x64/bundled/libs/debugpy/adapter/../../debugpy/launcher/../../debugpy/../debugpy/server/cli.py", line 284, in run_file
    runpy.run_path(target, run_name="__main__")
  File "/home/user/.vscode-server/extensions/ms-python.debugpy-2024.10.0-linux-x64/bundled/libs/debugpy/_vendored/pydevd/_pydevd_bundle/pydevd_runpy.py", line 321, in run_path
    return _run_module_code(code, init_globals, run_name,
  File "/home/user/.vscode-server/extensions/ms-python.debugpy-2024.10.0-linux-x64/bundled/libs/debugpy/_vendored/pydevd/_pydevd_bundle/pydevd_runpy.py", line 135, in _run_module_code
    _run_code(code, mod_globals, init_globals,
  File "/home/user/.vscode-server/extensions/ms-python.debugpy-2024.10.0-linux-x64/bundled/libs/debugpy/_vendored/pydevd/_pydevd_bundle/pydevd_runpy.py", line 124, in _run_code
    exec(code, run_globals)
  File "/data/SyL/Event_RGB/deepspeed_train.py", line 142, in <module>
    trainer.train()
  File "/home/user/anaconda3/envs/llava/lib/python3.10/site-packages/transformers/trainer.py", line 1539, in train
    return inner_training_loop(
  File "/home/user/anaconda3/envs/llava/lib/python3.10/site-packages/transformers/trainer.py", line 1869, in _inner_training_loop
    tr_loss_step = self.training_step(model, inputs)
  File "/home/user/anaconda3/envs/llava/lib/python3.10/site-packages/transformers/trainer.py", line 2772, in training_step
    loss = self.compute_loss(model, inputs)
  File "/home/user/anaconda3/envs/llava/lib/python3.10/site-packages/transformers/trainer.py", line 2795, in compute_loss
    outputs = model(**inputs)
  File "/home/user/anaconda3/envs/llava/lib/python3.10/site-packages/torch/nn/modules/module.py", line 1518, in _wrapped_call_impl
    return self._call_impl(*args, **kwargs)
  File "/home/user/anaconda3/envs/llava/lib/python3.10/site-packages/torch/nn/modules/module.py", line 1527, in _call_impl
    return forward_call(*args, **kwargs)
  File "/home/user/anaconda3/envs/llava/lib/python3.10/site-packages/accelerate/utils/operations.py", line 581, in forward
    return model_forward(*args, **kwargs)
  File "/home/user/anaconda3/envs/llava/lib/python3.10/site-packages/accelerate/utils/operations.py", line 569, in __call__
    return convert_to_fp32(self.model_forward(*args, **kwargs))
  File "/home/user/anaconda3/envs/llava/lib/python3.10/site-packages/torch/amp/autocast_mode.py", line 16, in decorate_autocast
    return func(*args, **kwargs)
  File "/data/SyL/Event_RGB/model/EventChatModel.py", line 248, in forward
    images_feature = self.visual_projecotr(images_feature)
  File "/data/SyL/Event_RGB/model/EventChatModel.py", line 248, in forward
    images_feature = self.visual_projecotr(images_feature)
  File "/home/user/.vscode-server/extensions/ms-python.debugpy-2024.10.0-linux-x64/bundled/libs/debugpy/_vendored/pydevd/_pydevd_bundle/pydevd_frame.py", line 988, in trace_dispatch
    self.do_wait_suspend(thread, frame, event, arg)
  File "/home/user/.vscode-server/extensions/ms-python.debugpy-2024.10.0-linux-x64/bundled/libs/debugpy/_vendored/pydevd/_pydevd_bundle/pydevd_frame.py", line 165, in do_wait_suspend
    self._args[0].do_wait_suspend(*args, **kwargs)
  File "/home/user/.vscode-server/extensions/ms-python.debugpy-2024.10.0-linux-x64/bundled/libs/debugpy/_vendored/pydevd/pydevd.py", line 2070, in do_wait_suspend
    keep_suspended = self._do_wait_suspend(thread, frame, event, arg, suspend_type, from_this_thread, frames_tracker)
  File "/home/user/.vscode-server/extensions/ms-python.debugpy-2024.10.0-linux-x64/bundled/libs/debugpy/_vendored/pydevd/pydevd.py", line 2106, in _do_wait_suspend
    time.sleep(0.01)
KeyboardInterrupt
Exception ignored in: <module 'threading' from '/home/user/anaconda3/envs/llava/lib/python3.10/threading.py'>
Traceback (most recent call last):
  File "/home/user/anaconda3/envs/llava/lib/python3.10/threading.py", line 1567, in _shutdown
    lock.acquire()
KeyboardInterrupt: